<?xml version="1.0"?>
<robot name="inst_kinsystem"
       xmlns:xi="http://www.w3.org/2001/XInclude"
       xmlns:gazebo="http://playerstage.sourceforge.net/gazebo/xmlschema/#gz"
       xmlns:model="http://playerstage.sourceforge.net/gazebo/xmlschema/#model"
       xmlns:sensor="http://playerstage.sourceforge.net/gazebo/xmlschema/#sensor"
       xmlns:body="http://playerstage.sourceforge.net/gazebo/xmlschema/#body"
       xmlns:geom="http://playerstage.sourceforge.net/gazebo/xmlschema/#geom"
       xmlns:joint="http://playerstage.sourceforge.net/gazebo/xmlschema/#joint"
       xmlns:interface="http://playerstage.sourceforge.net/gazebo/xmlschema/#interface"
       xmlns:rendering="http://playerstage.sourceforge.net/gazebo/xmlschema/#rendering"
       xmlns:renderable="http://playerstage.sourceforge.net/gazebo/xmlschema/#renderable"
       xmlns:controller="http://playerstage.sourceforge.net/gazebo/xmlschema/#controller"
       xmlns:physics="http://playerstage.sourceforge.net/gazebo/xmlschema/#physics">
  <link name="ROOT_link">
    <visual>
      <origin xyz="0 0 0" rpy="0 -0 0"/>
      <geometry>
        <mesh filename="model://cupboard/meshes/ROOT_link_mesh.dae" scale="1 1 1" />
      </geometry>
    </visual>
    <collision>
      <origin xyz="0 0 0" rpy="0 -0 0"/>
      <geometry>
        <mesh filename="model://cupboard/meshes/ROOT_link_mesh.dae" scale="1 1 1" />
      </geometry>
    </collision>
    <inertial>
      <mass value="20" />
      <origin xyz="0 0 1" rpy="0 0 0"/>
      <inertia ixx="1" ixy="0" ixz="0" iyy="1" iyz="0" izz="0"/>
    </inertial>
  </link>
  <gazebo reference="ROOT_link">
    <mu1>0.9</mu1>
    <mu2>0.9</mu2>
  </gazebo>
  <link name="ASKUL-GDH-CUPBOARD-BODYSET2_link">
    <visual>
      <origin xyz="0.171 0.288 0.08" rpy="0 -0 0"/>
      <geometry>
        <mesh filename="model://cupboard/meshes/ASKUL-GDH-CUPBOARD-BODYSET2_link_mesh.dae" scale="1 1 1" />
      </geometry>
    </visual>
    <collision>
      <origin xyz="0.171 0.288 0.08" rpy="0 -0 0"/>
      <geometry>
        <mesh filename="model://cupboard/meshes/ASKUL-GDH-CUPBOARD-BODYSET2_link_mesh.dae" scale="1 1 1" />
      </geometry>
    </collision>
    <inertial>
      <mass value="20" />
      <origin xyz="0 0 1" rpy="0 0 0"/>
      <inertia ixx="1" ixy="0" ixz="0" iyy="1" iyz="0" izz="0"/>
    </inertial>
  </link>
  <gazebo reference="ASKUL-GDH-CUPBOARD-BODYSET2_link">
    <mu1>0.9</mu1>
    <mu2>0.9</mu2>
  </gazebo>
  <link name="ASKUL-GDH-CUPBOARD-BODYSET3_link">
    <visual>
      <origin xyz="0.171 -0.288 0.08" rpy="0 -0 0"/>
      <geometry>
        <mesh filename="model://cupboard/meshes/ASKUL-GDH-CUPBOARD-BODYSET3_link_mesh.dae" scale="1 1 1" />
      </geometry>
    </visual>
    <collision>
      <origin xyz="0.171 -0.288 0.08" rpy="0 -0 0"/>
      <geometry>
        <mesh filename="model://cupboard/meshes/ASKUL-GDH-CUPBOARD-BODYSET3_link_mesh.dae" scale="1 1 1" />
      </geometry>
    </collision>
    <inertial>
      <mass value="20" />
      <origin xyz="0 0 1" rpy="0 0 0"/>
      <inertia ixx="1" ixy="0" ixz="0" iyy="1" iyz="0" izz="0"/>
    </inertial>
  </link>
  <gazebo reference="ASKUL-GDH-CUPBOARD-BODYSET3_link">
    <mu1>0.9</mu1>
    <mu2>0.9</mu2>
  </gazebo>
  <link name="ASKUL-GDH-CUPBOARD-BODYSET5_link">
    <visual>
      <origin xyz="0.171 0.288 0.885" rpy="0 -0 0"/>
      <geometry>
        <mesh filename="model://cupboard/meshes/ASKUL-GDH-CUPBOARD-BODYSET5_link_mesh.dae" scale="1 1 1" />
      </geometry>
    </visual>
    <collision>
      <origin xyz="0.171 0.288 0.885" rpy="0 -0 0"/>
      <geometry>
        <mesh filename="model://cupboard/meshes/ASKUL-GDH-CUPBOARD-BODYSET5_link_mesh.dae" scale="1 1 1" />
      </geometry>
    </collision>
    <inertial>
      <mass value="20" />
      <origin xyz="0 0 1" rpy="0 0 0"/>
      <inertia ixx="1" ixy="0" ixz="0" iyy="1" iyz="0" izz="0"/>
    </inertial>
  </link>
  <gazebo reference="ASKUL-GDH-CUPBOARD-BODYSET5_link">
    <mu1>0.9</mu1>
    <mu2>0.9</mu2>
  </gazebo>
  <link name="ASKUL-GDH-CUPBOARD-BODYSET6_link">
    <visual>
      <origin xyz="0.171 -0.288 0.885" rpy="0 -0 0"/>
      <geometry>
        <mesh filename="model://cupboard/meshes/ASKUL-GDH-CUPBOARD-BODYSET6_link_mesh.dae" scale="1 1 1" />
      </geometry>
    </visual>
    <collision>
      <origin xyz="0.171 -0.288 0.885" rpy="0 -0 0"/>
      <geometry>
        <mesh filename="model://cupboard/meshes/ASKUL-GDH-CUPBOARD-BODYSET6_link_mesh.dae" scale="1 1 1" />
      </geometry>
    </collision>
    <inertial>
      <mass value="20" />
      <origin xyz="0 0 1" rpy="0 0 0"/>
      <inertia ixx="1" ixy="0" ixz="0" iyy="1" iyz="0" izz="0"/>
    </inertial>
  </link>
  <gazebo reference="ASKUL-GDH-CUPBOARD-BODYSET6_link">
    <mu1>0.9</mu1>
    <mu2>0.9</mu2>
  </gazebo>
  <link name="ASKUL-GDH-CUPBOARD-BODYSET4_link">
    <visual>
      <origin xyz="0 0 0.822" rpy="0 -0 0"/>
      <geometry>
        <mesh filename="model://cupboard/meshes/ASKUL-GDH-CUPBOARD-BODYSET4_link_mesh.dae" scale="1 1 1" />
      </geometry>
    </visual>
    <collision>
      <origin xyz="0 0 0.822" rpy="0 -0 0"/>
      <geometry>
        <mesh filename="model://cupboard/meshes/ASKUL-GDH-CUPBOARD-BODYSET4_link_mesh.dae" scale="1 1 1" />
      </geometry>
    </collision>
    <inertial>
      <mass value="20" />
      <origin xyz="0 0 1" rpy="0 0 0"/>
      <inertia ixx="1" ixy="0" ixz="0" iyy="1" iyz="0" izz="0"/>
    </inertial>
  </link>
  <gazebo reference="ASKUL-GDH-CUPBOARD-BODYSET4_link">
    <mu1>0.9</mu1>
    <mu2>0.9</mu2>
  </gazebo>
  <joint name="DOOR-LOWER-LEFT" type="revolute">
    <parent link="ROOT_link"/>
    <child  link="ASKUL-GDH-CUPBOARD-BODYSET2_link"/>
    <origin xyz="0.171 0.288 0.08" rpy="0 -0 0 "/>
    <axis   xyz="0 0 1"/>
    <limit lower="0" upper="1.5708" effort="100" velocity="0.5" />
    <dynamics damping="0.2" friction="0" />
  </joint>
  <transmission type="pr2_mechanism_model/SimpleTransmission" name="DOOR-LOWER-LEFT_trans" >
    <actuator name="DOOR-LOWER-LEFT_motor" />
    <joint name="DOOR-LOWER-LEFT" />
    <mechanicalReduction>1</mechanicalReduction>
  </transmission>
  <gazebo reference="DOOR-LOWER-LEFT">
    <cfmDamping>0.4</cfmDamping>
  </gazebo>
  <joint name="DOOR-LOWER-RIGHT" type="revolute">
    <parent link="ROOT_link"/>
    <child  link="ASKUL-GDH-CUPBOARD-BODYSET3_link"/>
    <origin xyz="0.171 -0.288 0.08" rpy="0 -0 0 "/>
    <axis   xyz="0 0 -1"/>
    <limit lower="0" upper="1.5708" effort="100" velocity="0.5" />
    <dynamics damping="0.2" friction="0" />
  </joint>
  <transmission type="pr2_mechanism_model/SimpleTransmission" name="DOOR-LOWER-RIGHT_trans" >
    <actuator name="DOOR-LOWER-RIGHT_motor" />
    <joint name="DOOR-LOWER-RIGHT" />
    <mechanicalReduction>1</mechanicalReduction>
  </transmission>
  <gazebo reference="DOOR-LOWER-RIGHT">
    <cfmDamping>0.4</cfmDamping>
  </gazebo>
  <joint name="DOOR-UPPER-LEFT" type="revolute">
    <parent link="ROOT_link"/>
    <child  link="ASKUL-GDH-CUPBOARD-BODYSET5_link"/>
    <origin xyz="0.171 0.288 0.885" rpy="0 -0 0 "/>
    <axis   xyz="0 0 1"/>
    <limit lower="0" upper="1.5708" effort="100" velocity="0.5" />
    <dynamics damping="0.2" friction="0" />
  </joint>
  <transmission type="pr2_mechanism_model/SimpleTransmission" name="DOOR-UPPER-LEFT_trans" >
    <actuator name="DOOR-UPPER-LEFT_motor" />
    <joint name="DOOR-UPPER-LEFT" />
    <mechanicalReduction>1</mechanicalReduction>
  </transmission>
  <gazebo reference="DOOR-UPPER-LEFT">
    <cfmDamping>0.4</cfmDamping>
  </gazebo>
  <joint name="DOOR-UPPER-RIGHT" type="revolute">
    <parent link="ROOT_link"/>
    <child  link="ASKUL-GDH-CUPBOARD-BODYSET6_link"/>
    <origin xyz="0.171 -0.288 0.885" rpy="0 -0 0 "/>
    <axis   xyz="0 0 -1"/>
    <limit lower="0" upper="1.5708" effort="100" velocity="0.5" />
    <dynamics damping="0.2" friction="0" />
  </joint>
  <transmission type="pr2_mechanism_model/SimpleTransmission" name="DOOR-UPPER-RIGHT_trans" >
    <actuator name="DOOR-UPPER-RIGHT_motor" />
    <joint name="DOOR-UPPER-RIGHT" />
    <mechanicalReduction>1</mechanicalReduction>
  </transmission>
  <gazebo reference="DOOR-UPPER-RIGHT">
    <cfmDamping>0.4</cfmDamping>
  </gazebo>
  <joint name="DRAWER" type="prismatic">
    <parent link="ROOT_link"/>
    <child  link="ASKUL-GDH-CUPBOARD-BODYSET4_link"/>
    <origin xyz="0 0 0.822" rpy="0 -0 0 "/>
    <axis   xyz="1 0 0"/>
    <limit lower="0" upper="0.353" effort="100" velocity="0.01" />
    <dynamics damping="0.2" friction="0" />
  </joint>
  <transmission type="pr2_mechanism_model/SimpleTransmission" name="DRAWER_trans" >
    <actuator name="DRAWER_motor" />
    <joint name="DRAWER" />
    <mechanicalReduction>1</mechanicalReduction>
  </transmission>
  <gazebo reference="DRAWER">
    <cfmDamping>0.4</cfmDamping>
  </gazebo>
</robot>
